[2025-06-17 14:13:08,404] {taskinstance.py:896} INFO - Dependencies all met for <TaskInstance: load_csvs_to_postgres.load_csv_files 2025-06-17T14:13:04.319335+00:00 [queued]>
[2025-06-17 14:13:08,429] {taskinstance.py:896} INFO - Dependencies all met for <TaskInstance: load_csvs_to_postgres.load_csv_files 2025-06-17T14:13:04.319335+00:00 [queued]>
[2025-06-17 14:13:08,430] {taskinstance.py:1087} INFO - 
--------------------------------------------------------------------------------
[2025-06-17 14:13:08,430] {taskinstance.py:1088} INFO - Starting attempt 1 of 1
[2025-06-17 14:13:08,430] {taskinstance.py:1089} INFO - 
--------------------------------------------------------------------------------
[2025-06-17 14:13:08,442] {taskinstance.py:1107} INFO - Executing <Task(PythonOperator): load_csv_files> on 2025-06-17T14:13:04.319335+00:00
[2025-06-17 14:13:08,454] {standard_task_runner.py:52} INFO - Started process 208 to run task
[2025-06-17 14:13:08,475] {standard_task_runner.py:76} INFO - Running: ['***', 'tasks', 'run', 'load_csvs_to_postgres', 'load_csv_files', '2025-06-17T14:13:04.319335+00:00', '--job-id', '21', '--pool', 'default_pool', '--raw', '--subdir', 'DAGS_FOLDER/load_to_postgres.py', '--cfg-path', '/tmp/tmpa7dei4o5', '--error-file', '/tmp/tmp5wk0tr3p']
[2025-06-17 14:13:08,476] {standard_task_runner.py:77} INFO - Job 21: Subtask load_csv_files
[2025-06-17 14:13:08,804] {logging_mixin.py:104} INFO - Running <TaskInstance: load_csvs_to_postgres.load_csv_files 2025-06-17T14:13:04.319335+00:00 [running]> on host af20c1caf450
[2025-06-17 14:13:08,948] {taskinstance.py:1302} INFO - Exporting the following env vars:
AIRFLOW_CTX_DAG_OWNER=***
AIRFLOW_CTX_DAG_ID=load_csvs_to_postgres
AIRFLOW_CTX_TASK_ID=load_csv_files
AIRFLOW_CTX_EXECUTION_DATE=2025-06-17T14:13:04.319335+00:00
AIRFLOW_CTX_DAG_RUN_ID=manual__2025-06-17T14:13:04.319335+00:00
[2025-06-17 14:13:08,984] {taskinstance.py:1501} ERROR - Task failed with exception
Traceback (most recent call last):
  File "/home/airflow/.local/lib/python3.6/site-packages/airflow/models/taskinstance.py", line 1157, in _run_raw_task
    self._prepare_and_execute_task_with_callbacks(context, task)
  File "/home/airflow/.local/lib/python3.6/site-packages/airflow/models/taskinstance.py", line 1331, in _prepare_and_execute_task_with_callbacks
    result = self._execute_task(context, task_copy)
  File "/home/airflow/.local/lib/python3.6/site-packages/airflow/models/taskinstance.py", line 1361, in _execute_task
    result = task_copy.execute(context=context)
  File "/home/airflow/.local/lib/python3.6/site-packages/airflow/operators/python.py", line 150, in execute
    return_value = self.execute_callable()
  File "/home/airflow/.local/lib/python3.6/site-packages/airflow/operators/python.py", line 161, in execute_callable
    return self.python_callable(*self.op_args, **self.op_kwargs)
  File "/opt/airflow/dags/load_to_postgres.py", line 26, in load_all_tables
    load_csv_to_postgres("dim_customer", f"{base_path}/customers.csv")
  File "/opt/airflow/dags/load_to_postgres.py", line 18, in load_csv_to_postgres
    cur.copy_expert(f"COPY {table_name} FROM STDIN WITH CSV", f)
psycopg2.errors.UniqueViolation: duplicate key value violates unique constraint "dim_customer_pkey"
DETAIL:  Key (customerid)=(12370.0) already exists.
CONTEXT:  COPY dim_customer, line 22

[2025-06-17 14:13:08,998] {taskinstance.py:1551} INFO - Marking task as FAILED. dag_id=load_csvs_to_postgres, task_id=load_csv_files, execution_date=20250617T141304, start_date=20250617T141308, end_date=20250617T141308
[2025-06-17 14:13:09,074] {local_task_job.py:151} INFO - Task exited with return code 1
